Workbook

Sheet Dashboard
A1: DASHBOARD — RESUMEN EJECUTIVO DEL PROYECTO
A2: Se alimenta automáticamente de las demás hojas
A3: INDICADOR | B3: VALOR
A4: Gasto Total Anual en Químicos (€) | B4: ='Inventario Químicos'!U55 -> 0
A5: Nº de Productos | B5: =COUNTA('Inventario Químicos'!C5:C54) -> 0
A6: Nº de Proveedores | B6: =COUNTA(Proveedores!B4:B28) -> 0
A7: Nº Productos Precio Fijo | B7: =COUNTIF('Inventario Químicos'!L5:L54,"Fijo") -> 0
A8: Nº Productos Precio Indexado | B8: =COUNTIF('Inventario Químicos'!L5:L54,"Indexado") -> 0
A9: Nº Productos Spot (sin contrato) | B9: =COUNTIF('Inventario Químicos'!L5:L54,"Spot*") -> 0
A10: Potencial Ahorro Total Teórico (€) | B10: ='Inventario Químicos'!AA55 -> 0
A11: Potencial Ahorro (% sobre gasto) | B11: =IF(B4>0,B10/B4,"")
A14: DISTRIBUCIÓN POR CLASIFICACIÓN (Pareto)
A15: Clasificación | B15: Nº Productos | C15: Gasto (€) | D15: % del Total
A16: Commodity | B16: =COUNTIF('Inventario Químicos'!H5:H54,"Commodity") -> 0 | C16: =SUMIFS('Inventario Químicos'!U5:U54,'Inventario Químicos'!H5:H54,"Commodity") -> 0 | D16: =IF(B4>0,C16/B4,"")
A17: Semi-especialidad | B17: =COUNTIF('Inventario Químicos'!H5:H54,"Semi-especialidad") -> 0 | C17: =SUMIFS('Inventario Químicos'!U5:U54,'Inventario Químicos'!H5:H54,"Semi-especialidad") -> 0 | D17: =IF(B4>0,C17/B4,"")
A18: Especialidad | B18: =COUNTIF('Inventario Químicos'!H5:H54,"Especialidad") -> 0 | C18: =SUMIFS('Inventario Químicos'!U5:U54,'Inventario Químicos'!H5:H54,"Especialidad") -> 0 | D18: =IF(B4>0,C18/B4,"")
A21: DISTRIBUCIÓN POR FORMATO DE ENVASE
A22: Formato | B22: Nº Productos | C22: Oportunidad cambio formato
A23: Bidón/Garrafa | B23: =COUNTIF('Inventario Químicos'!M5:M54,"Bidón/Garrafa") -> 0
A24: IBC 1000L | B24: =COUNTIF('Inventario Químicos'!M5:M54,"IBC 1000L") -> 0
A25: Contenedor 20-24tm | B25: =COUNTIF('Inventario Químicos'!M5:M54,"Contenedor 20-24tm") -> 0
A26: Cisterna | B26: =COUNTIF('Inventario Químicos'!M5:M54,"Cisterna") -> 0
A29: SALUD CONTRACTUAL (de Auditoría Contractual)
A30: Condición | B30: Nº Casos | C30: Nivel de riesgo
A31: Proveedores sin contrato formal | C31: A revisar
A32: Contratos con take-or-pay rígido | C32: Riesgo alto
A33: Fórmulas de revisión asimétricas | C33: Riesgo medio
A34: Rappels existentes NO cobrados | C34: Ahorro inmediato
A35: Sin cláusula de salida | C35: Riesgo alto
A38: INSTRUCCIONES DE USO
A39: 1. INVENTARIO QUÍMICOS: Completar todos los productos. Las fórmulas calculan €/kg materia activa, gap vs benchmark y potencial de ahorro.
A40: 2. AUDITORÍA CONTRACTUAL: Para cada proveedor, auditar TODAS las condiciones (Cap.6): pago, duración, volumen, revisión, rappels, envases, servicio.
A41: 3. BASELINE (ACTA PRECIOS): Completar y FIRMAR antes del primer RFQ. Es la base legal del success fee.
A42: 4. BENCHMARKING: Solicitar 3 cotizaciones DAP + DataComex + ICIS. Comparar con precio cliente normalizado.
A43: 5. HISTÓRICO PRECIOS: 24 meses de facturas. La media ponderada 12m es el baseline estándar.
A44: 6. VISITA PLANTA: Usar el checklist durante la visita. Completar el informe el MISMO DÍA.
A45: 7. PROVEEDORES: Registro de contactos. Incluye distribuidores españoles de referencia del Manual.
A46: 8. DASHBOARD: Se calcula automáticamente. Completar manualmente los campos de entrada restantes.
A48: REGLA DE ORO: No cambiamos el mecanismo de precio (Cap.4.4). Fijo→mejor fijo. Indexado→menor prima.
A49: Celdas AMARILLAS con texto AZUL = campos de entrada. Celdas BLANCAS con texto NEGRO = fórmulas (no tocar).

Sheet Inventario Químicos
A1: INVENTARIO DE PRODUCTOS QUÍMICOS
A2: Herramienta de recogida de datos — Modelo ERA Group success fee
B3: IDENTIFICACIÓN DEL PRODUCTO | J3: PROVEEDOR Y MECANISMO | M3: FORMATO | O3: ANÁLISIS DE PRECIO (Cap.3) | T3: CONSUMO | V3: PARETO | W3: INDEXADOS (Cap.4) | Y3: BENCHMARKING (Cap.7) | AB3: PLANTA
A4: Nº | B4: Familia | C4: Nombre Comercial | D4: Principio Activo | E4: Concentración (%) | F4: Calidad / Grado | G4: Código TARIC | H4: Clasificación | I4: Aplicación / Uso | J4: Proveedor Actual | K4: Fabricante | L4: Tipo Precio | M4: Formato Envase | N4: Capacidad (kg/L) | O4: Precio Producto (€/kg) | P4: Coste Transporte (€/kg) | Q4: Incoterm | R4: €/kg Materia Activa | S4: €/kg MA + Transporte | T4: Consumo Anual (kg MA) | U4: Gasto Anual (€) | V4: % Acumulado Pareto | W4: Índice ICIS (si aplica) | X4: Prima (€/tm) | Y4: Precio Benchmark (€/kg MA) | Z4: Gap vs Benchmark (%) | AA4: Potencial Ahorro (€) | AB4: Notas Visita Planta
A5: 1 | R5: =IF(AND(O5<>"",E5<>"",E5>0),O5/(E5/100),"") | S5: =IF(AND(O5<>"",E5<>"",E5>0),(O5+IF(P5<>"",P5,0))/(E5/100),"") | U5: =IF(AND(S5<>"",T5<>""),S5*T5,"") | Z5: =IF(AND(S5<>"",Y5<>"",Y5>0),(S5-Y5)/Y5,"") | AA5: =IF(AND(S5<>"",Y5<>"",T5<>""),MAX(0,(S5-Y5)*T5),"")
A6: 2 | R6: =IF(AND(O6<>"",E6<>"",E6>0),O6/(E6/100),"") | S6: =IF(AND(O6<>"",E6<>"",E6>0),(O6+IF(P6<>"",P6,0))/(E6/100),"") | U6: =IF(AND(S6<>"",T6<>""),S6*T6,"") | Z6: =IF(AND(S6<>"",Y6<>"",Y6>0),(S6-Y6)/Y6,"") | AA6: =IF(AND(S6<>"",Y6<>"",T6<>""),MAX(0,(S6-Y6)*T6),"")
A7: 3 | R7: =IF(AND(O7<>"",E7<>"",E7>0),O7/(E7/100),"") | S7: =IF(AND(O7<>"",E7<>"",E7>0),(O7+IF(P7<>"",P7,0))/(E7/100),"") | U7: =IF(AND(S7<>"",T7<>""),S7*T7,"") | Z7: =IF(AND(S7<>"",Y7<>"",Y7>0),(S7-Y7)/Y7,"") | AA7: =IF(AND(S7<>"",Y7<>"",T7<>""),MAX(0,(S7-Y7)*T7),"")
A8: 4 | R8: =IF(AND(O8<>"",E8<>"",E8>0),O8/(E8/100),"") | S8: =IF(AND(O8<>"",E8<>"",E8>0),(O8+IF(P8<>"",P8,0))/(E8/100),"") | U8: =IF(AND(S8<>"",T8<>""),S8*T8,"") | Z8: =IF(AND(S8<>"",Y8<>"",Y8>0),(S8-Y8)/Y8,"") | AA8: =IF(AND(S8<>"",Y8<>"",T8<>""),MAX(0,(S8-Y8)*T8),"")
A9: 5 | R9: =IF(AND(O9<>"",E9<>"",E9>0),O9/(E9/100),"") | S9: =IF(AND(O9<>"",E9<>"",E9>0),(O9+IF(P9<>"",P9,0))/(E9/100),"") | U9: =IF(AND(S9<>"",T9<>""),S9*T9,"") | Z9: =IF(AND(S9<>"",Y9<>"",Y9>0),(S9-Y9)/Y9,"") | AA9: =IF(AND(S9<>"",Y9<>"",T9<>""),MAX(0,(S9-Y9)*T9),"")
A10: 6 | R10: =IF(AND(O10<>"",E10<>"",E10>0),O10/(E10/100),"") | S10: =IF(AND(O10<>"",E10<>"",E10>0),(O10+IF(P10<>"",P10,0))/(E10/100),"") | U10: =IF(AND(S10<>"",T10<>""),S10*T10,"") | Z10: =IF(AND(S10<>"",Y10<>"",Y10>0),(S10-Y10)/Y10,"") | AA10: =IF(AND(S10<>"",Y10<>"",T10<>""),MAX(0,(S10-Y10)*T10),"")
A11: 7 | R11: =IF(AND(O11<>"",E11<>"",E11>0),O11/(E11/100),"") | S11: =IF(AND(O11<>"",E11<>"",E11>0),(O11+IF(P11<>"",P11,0))/(E11/100),"") | U11: =IF(AND(S11<>"",T11<>""),S11*T11,"") | Z11: =IF(AND(S11<>"",Y11<>"",Y11>0),(S11-Y11)/Y11,"") | AA11: =IF(AND(S11<>"",Y11<>"",T11<>""),MAX(0,(S11-Y11)*T11),"")
A12: 8 | R12: =IF(AND(O12<>"",E12<>"",E12>0),O12/(E12/100),"") | S12: =IF(AND(O12<>"",E12<>"",E12>0),(O12+IF(P12<>"",P12,0))/(E12/100),"") | U12: =IF(AND(S12<>"",T12<>""),S12*T12,"") | Z12: =IF(AND(S12<>"",Y12<>"",Y12>0),(S12-Y12)/Y12,"") | AA12: =IF(AND(S12<>"",Y12<>"",T12<>""),MAX(0,(S12-Y12)*T12),"")
A13: 9 | R13: =IF(AND(O13<>"",E13<>"",E13>0),O13/(E13/100),"") | S13: =IF(AND(O13<>"",E13<>"",E13>0),(O13+IF(P13<>"",P13,0))/(E13/100),"") | U13: =IF(AND(S13<>"",T13<>""),S13*T13,"") | Z13: =IF(AND(S13<>"",Y13<>"",Y13>0),(S13-Y13)/Y13,"") | AA13: =IF(AND(S13<>"",Y13<>"",T13<>""),MAX(0,(S13-Y13)*T13),"")
A14: 10 | R14: =IF(AND(O14<>"",E14<>"",E14>0),O14/(E14/100),"") | S14: =IF(AND(O14<>"",E14<>"",E14>0),(O14+IF(P14<>"",P14,0))/(E14/100),"") | U14: =IF(AND(S14<>"",T14<>""),S14*T14,"") | Z14: =IF(AND(S14<>"",Y14<>"",Y14>0),(S14-Y14)/Y14,"") | AA14: =IF(AND(S14<>"",Y14<>"",T14<>""),MAX(0,(S14-Y14)*T14),"")
A15: 11 | R15: =IF(AND(O15<>"",E15<>"",E15>0),O15/(E15/100),"") | S15: =IF(AND(O15<>"",E15<>"",E15>0),(O15+IF(P15<>"",P15,0))/(E15/100),"") | U15: =IF(AND(S15<>"",T15<>""),S15*T15,"") | Z15: =IF(AND(S15<>"",Y15<>"",Y15>0),(S15-Y15)/Y15,"") | AA15: =IF(AND(S15<>"",Y15<>"",T15<>""),MAX(0,(S15-Y15)*T15),"")
A16: 12 | R16: =IF(AND(O16<>"",E16<>"",E16>0),O16/(E16/100),"") | S16: =IF(AND(O16<>"",E16<>"",E16>0),(O16+IF(P16<>"",P16,0))/(E16/100),"") | U16: =IF(AND(S16<>"",T16<>""),S16*T16,"") | Z16: =IF(AND(S16<>"",Y16<>"",Y16>0),(S16-Y16)/Y16,"") | AA16: =IF(AND(S16<>"",Y16<>"",T16<>""),MAX(0,(S16-Y16)*T16),"")
... A54: 50 | R54: =IF(AND(O54<>"",E54<>"",E54>0),O54/(E54/100),"") | S54: =IF(AND(O54<>"",E54<>"",E54>0),(O54+IF(P54<>"",P54,0))/(E54/100),"") | U54: =IF(AND(S54<>"",T54<>""),S54*T54,"") | Z54: =IF(AND(S54<>"",Y54<>"",Y54>0),(S54-Y54)/Y54,"") | AA54: =IF(AND(S54<>"",Y54<>"",T54<>""),MAX(0,(S54-Y54)*T54),"")
S55: TOTALES | T55: =SUM(T5:T54) -> 0 | U55: =SUM(U5:U54) -> 0 | AA55: =SUM(AA5:AA54) -> 0
A57: LEYENDA: Celdas amarillas = campos de entrada (rellenar). Celdas blancas = fórmulas automáticas (no modificar). €/kg MA = precio normalizado por materia activa (Cap.3 del manual).
A58: PRECIO: Introducir siempre el precio del producto tal cual se factura (€/kg producto). La fórmula calcula €/kg de materia activa automáticamente.
A59: TRANSPORTE: Si el Incoterm es DAP/DDP, dejar transporte en blanco (ya incluido). Si es EXW/FCA, introducir el coste de transporte por kg.

Sheet Auditoría Contractual
A1: AUDITORÍA DE CONDICIONES CONTRACTUALES
A2: Capítulo 6 del Manual — Revisar CADA relación proveedor-producto
A3: A) CONDICIONES CONTRACTUALES POR PROVEEDOR
A4: Nº | B4: Proveedor | C4: Producto(s) Principal(es) | D4: Plazo Pago (días) | E4: Dto. Pronto Pago (%) | F4: ¿Compensa PP? | G4: Duración Contrato | H4: Vencimiento | I4: Cláusula Salida | J4: Tipo Volumen | K4: Vol. Referencia (tm/año) | L4: Banda Mínima (%) | M4: Banda Máxima (%) | N4: Penalización Take-or-Pay | O4: Fórmula Revisión Precios | P4: Simétrica (Sí/No)
A5: 1 | F5: =IF(AND(E5<>"",D5<>"",E5>0),IF((E5/(D5-10)*365)>0.07,"NO (>"&TEXT(E5/(D5-10)*365,"0%")&" anualizado)","SÍ ("&TEXT(E5/(D5-10)*365,"0%")&" anualizado)"),"")
A6: 2 | F6: =IF(AND(E6<>"",D6<>"",E6>0),IF((E6/(D6-10)*365)>0.07,"NO (>"&TEXT(E6/(D6-10)*365,"0%")&" anualizado)","SÍ ("&TEXT(E6/(D6-10)*365,"0%")&" anualizado)"),"")
A7: 3 | F7: =IF(AND(E7<>"",D7<>"",E7>0),IF((E7/(D7-10)*365)>0.07,"NO (>"&TEXT(E7/(D7-10)*365,"0%")&" anualizado)","SÍ ("&TEXT(E7/(D7-10)*365,"0%")&" anualizado)"),"")
A8: 4 | F8: =IF(AND(E8<>"",D8<>"",E8>0),IF((E8/(D8-10)*365)>0.07,"NO (>"&TEXT(E8/(D8-10)*365,"0%")&" anualizado)","SÍ ("&TEXT(E8/(D8-10)*365,"0%")&" anualizado)"),"")
A9: 5 | F9: =IF(AND(E9<>"",D9<>"",E9>0),IF((E9/(D9-10)*365)>0.07,"NO (>"&TEXT(E9/(D9-10)*365,"0%")&" anualizado)","SÍ ("&TEXT(E9/(D9-10)*365,"0%")&" anualizado)"),"")
A10: 6 | F10: =IF(AND(E10<>"",D10<>"",E10>0),IF((E10/(D10-10)*365)>0.07,"NO (>"&TEXT(E10/(D10-10)*365,"0%")&" anualizado)","SÍ ("&TEXT(E10/(D10-10)*365,"0%")&" anualizado)"),"")
A11: 7 | F11: =IF(AND(E11<>"",D11<>"",E11>0),IF((E11/(D11-10)*365)>0.07,"NO (>"&TEXT(E11/(D11-10)*365,"0%")&" anualizado)","SÍ ("&TEXT(E11/(D11-10)*365,"0%")&" anualizado)"),"")
A12: 8 | F12: =IF(AND(E12<>"",D12<>"",E12>0),IF((E12/(D12-10)*365)>0.07,"NO (>"&TEXT(E12/(D12-10)*365,"0%")&" anualizado)","SÍ ("&TEXT(E12/(D12-10)*365,"0%")&" anualizado)"),"")
A13: 9 | F13: =IF(AND(E13<>"",D13<>"",E13>0),IF((E13/(D13-10)*365)>0.07,"NO (>"&TEXT(E13/(D13-10)*365,"0%")&" anualizado)","SÍ ("&TEXT(E13/(D13-10)*365,"0%")&" anualizado)"),"")
A14: 10 | F14: =IF(AND(E14<>"",D14<>"",E14>0),IF((E14/(D14-10)*365)>0.07,"NO (>"&TEXT(E14/(D14-10)*365,"0%")&" anualizado)","SÍ ("&TEXT(E14/(D14-10)*365,"0%")&" anualizado)"),"")
A15: 11 | F15: =IF(AND(E15<>"",D15<>"",E15>0),IF((E15/(D15-10)*365)>0.07,"NO (>"&TEXT(E15/(D15-10)*365,"0%")&" anualizado)","SÍ ("&TEXT(E15/(D15-10)*365,"0%")&" anualizado)"),"")
A16: 12 | F16: =IF(AND(E16<>"",D16<>"",E16>0),IF((E16/(D16-10)*365)>0.07,"NO (>"&TEXT(E16/(D16-10)*365,"0%")&" anualizado)","SÍ ("&TEXT(E16/(D16-10)*365,"0%")&" anualizado)"),"")
... A29: 25 | F29: =IF(AND(E29<>"",D29<>"",E29>0),IF((E29/(D29-10)*365)>0.07,"NO (>"&TEXT(E29/(D29-10)*365,"0%")&" anualizado)","SÍ ("&TEXT(E29/(D29-10)*365,"0%")&" anualizado)"),"")
A32: B) CONDICIONES LOGÍSTICAS, SERVICIO Y ENVASES
A33: Nº | B33: Proveedor | C33: Producto | D33: Incoterm | E33: Formato Actual | F33: Formato Óptimo | G33: ¿Stock Consigna? | H33: Rappel Existente | I33: ¿Rappel Cobrado? | J33: Servicio Técnico Incluido | K33: Equipos en Comodato | L33: Gestión Envases Vacíos | M33: Cláusula MFN | N33: Observaciones
A34: 1
A35: 2
A36: 3
A37: 4
A38: 5
A39: 6
A40: 7
A41: 8
A42: 9
A43: 10
A44: 11
A45: 12
... A58: 25
A61: C) SCORING RESUMEN — ESTADO DE CONDICIONES POR PROVEEDOR
A62: Puntuar cada condición: 1=Mal (riesgo/sobrecoste) · 2=Mejorable · 3=Aceptable · 4=Bien negociado. Media <2.5 = prioridad alta de renegociación.
A63: Proveedor | B63: Pago | C63: Duración | D63: Volumen | E63: Revisión Precios | F63: Logística | G63: Rappels | H63: Envases | I63: Servicio | J63: MEDIA
J64: =IF(COUNTA(B64:I64)>0,AVERAGE(B64:I64),"")
J65: =IF(COUNTA(B65:I65)>0,AVERAGE(B65:I65),"")
J66: =IF(COUNTA(B66:I66)>0,AVERAGE(B66:I66),"")
J67: =IF(COUNTA(B67:I67)>0,AVERAGE(B67:I67),"")
J68: =IF(COUNTA(B68:I68)>0,AVERAGE(B68:I68),"")
...

Sheet Baseline (Acta Precios)
A1: ACTA DE PRECIOS DE REFERENCIA (BASELINE)
A2: Este documento establece el precio de referencia verificado para cada producto. Es la base del cálculo del ahorro y del success fee de ERA.
A4: Nº | B4: Producto | C4: Materia Activa | D4: Concentración (%) | E4: Proveedor Actual | F4: Tipo Precio | G4: Periodo Cálculo | H4: Vol. Referencia (tm/año) | I4: Precio Pagado (€/kg prod.) | J4: €/kg Materia Activa (baseline) | K4: Prima Actual (€/tm) (solo indexados) | L4: Índice ICIS Referencia (solo indexados) | M4: Fórmula Cálculo Ahorro | N4: Fuente Verificación
A5: 1 | J5: =IF(AND(I5<>"",D5<>"",D5>0),I5/(D5/100),"") | M5: =IF(F5="Fijo","(Baseline fijo - Precio nuevo fijo) × Vol. real",IF(F5="Indexado","(Prima anterior - Prima nueva) × Vol. real","N/A")) -> N/A
A6: 2 | J6: =IF(AND(I6<>"",D6<>"",D6>0),I6/(D6/100),"") | M6: =IF(F6="Fijo","(Baseline fijo - Precio nuevo fijo) × Vol. real",IF(F6="Indexado","(Prima anterior - Prima nueva) × Vol. real","N/A")) -> N/A
A7: 3 | J7: =IF(AND(I7<>"",D7<>"",D7>0),I7/(D7/100),"") | M7: =IF(F7="Fijo","(Baseline fijo - Precio nuevo fijo) × Vol. real",IF(F7="Indexado","(Prima anterior - Prima nueva) × Vol. real","N/A")) -> N/A
A8: 4 | J8: =IF(AND(I8<>"",D8<>"",D8>0),I8/(D8/100),"") | M8: =IF(F8="Fijo","(Baseline fijo - Precio nuevo fijo) × Vol. real",IF(F8="Indexado","(Prima anterior - Prima nueva) × Vol. real","N/A")) -> N/A
A9: 5 | J9: =IF(AND(I9<>"",D9<>"",D9>0),I9/(D9/100),"") | M9: =IF(F9="Fijo","(Baseline fijo - Precio nuevo fijo) × Vol. real",IF(F9="Indexado","(Prima anterior - Prima nueva) × Vol. real","N/A")) -> N/A
A10: 6 | J10: =IF(AND(I10<>"",D10<>"",D10>0),I10/(D10/100),"") | M10: =IF(F10="Fijo","(Baseline fijo - Precio nuevo fijo) × Vol. real",IF(F10="Indexado","(Prima anterior - Prima nueva) × Vol. real","N/A")) -> N/A
A11: 7 | J11: =IF(AND(I11<>"",D11<>"",D11>0),I11/(D11/100),"") | M11: =IF(F11="Fijo","(Baseline fijo - Precio nuevo fijo) × Vol. real",IF(F11="Indexado","(Prima anterior - Prima nueva) × Vol. real","N/A")) -> N/A
A12: 8 | J12: =IF(AND(I12<>"",D12<>"",D12>0),I12/(D12/100),"") | M12: =IF(F12="Fijo","(Baseline fijo - Precio nuevo fijo) × Vol. real",IF(F12="Indexado","(Prima anterior - Prima nueva) × Vol. real","N/A")) -> N/A
A13: 9 | J13: =IF(AND(I13<>"",D13<>"",D13>0),I13/(D13/100),"") | M13: =IF(F13="Fijo","(Baseline fijo - Precio nuevo fijo) × Vol. real",IF(F13="Indexado","(Prima anterior - Prima nueva) × Vol. real","N/A")) -> N/A
A14: 10 | J14: =IF(AND(I14<>"",D14<>"",D14>0),I14/(D14/100),"") | M14: =IF(F14="Fijo","(Baseline fijo - Precio nuevo fijo) × Vol. real",IF(F14="Indexado","(Prima anterior - Prima nueva) × Vol. real","N/A")) -> N/A
A15: 11 | J15: =IF(AND(I15<>"",D15<>"",D15>0),I15/(D15/100),"") | M15: =IF(F15="Fijo","(Baseline fijo - Precio nuevo fijo) × Vol. real",IF(F15="Indexado","(Prima anterior - Prima nueva) × Vol. real","N/A")) -> N/A
A16: 12 | J16: =IF(AND(I16<>"",D16<>"",D16>0),I16/(D16/100),"") | M16: =IF(F16="Fijo","(Baseline fijo - Precio nuevo fijo) × Vol. real",IF(F16="Indexado","(Prima anterior - Prima nueva) × Vol. real","N/A")) -> N/A
... A54: 50 | J54: =IF(AND(I54<>"",D54<>"",D54>0),I54/(D54/100),"") | M54: =IF(F54="Fijo","(Baseline fijo - Precio nuevo fijo) × Vol. real",IF(F54="Indexado","(Prima anterior - Prima nueva) × Vol. real","N/A")) -> N/A
A57: FIRMAS DE CONFORMIDAD
A58: Ambas partes confirman que los precios de referencia arriba indicados reflejan fielmente los precios pagados en el periodo de cálculo y aceptan estos como baseline para el cálculo del ahorro del proyecto.
A60: Por el Cliente: ________________________ Cargo: ________________________ Fecha: ___/___/______
A61: Por ERA Group: ________________________ Cargo: ________________________ Fecha: ___/___/______
A63: CLÁUSULA: Para productos con precio fijo, el ahorro = (Baseline − Precio nuevo) × Volumen real 12 meses. Para productos indexados, el ahorro = (Prima anterior − Prima nueva) × Volumen real. Cambios de mecanismo de precio (fijo→indexado o viceversa) NO computan para el success fee (Cap. 4.4 del Manual).

Sheet Benchmarking
A1: ANÁLISIS COMPARATIVO DE PRECIOS DE MERCADO
A2: Capítulo 7 del Manual — Fuentes España + Internacionales
A3: Nº | B3: Producto | C3: Materia Activa | D3: Código TARIC | E3: Precio Cliente (€/kg MA) | F3: Cotiz. 1 Distribuidor | G3: Cotiz. 2 Distribuidor | H3: Cotiz. 3 Distribuidor | I3: Media Cotiz. (€/kg MA) | J3: DataComex CIF Import (€/kg) | K3: CIF + Margen (puesto planta) | L3: ICIS Index (€/tm) | M3: ICIS + Prima (€/kg MA) | N3: Precio Fabricante Directo (€/kg MA) | O3: Mejor Benchmark (€/kg MA) | P3: Gap Cliente vs Benchmark (%) | Q3: Ahorro Potencial (€/año) | R3: Fuente / Notas
A4: 1 | I4: =IF(COUNTA(F4:H4)>0,AVERAGE(F4:H4),"") | K4: =IF(J4<>"",J4*1.15,"") | M4: =IF(AND(L4<>""),"Calcular manual","") | O4: =IF(COUNTA(I4,K4,N4)>0,MIN(IF(I4<>"",I4,999),IF(K4<>"",K4,999),IF(N4<>"",N4,999)),"") -> 999 | P4: =IF(AND(E4<>"",O4<>"",O4>0,O4<999),(E4-O4)/O4,"") | Q4: =IF(AND(E4<>"",O4<>"",O4<999),MAX(0,E4-O4)*0,"Vincular vol.") -> Vincular vol.
A5: 2 | I5: =IF(COUNTA(F5:H5)>0,AVERAGE(F5:H5),"") | K5: =IF(J5<>"",J5*1.15,"") | M5: =IF(AND(L5<>""),"Calcular manual","") | O5: =IF(COUNTA(I5,K5,N5)>0,MIN(IF(I5<>"",I5,999),IF(K5<>"",K5,999),IF(N5<>"",N5,999)),"") -> 999 | P5: =IF(AND(E5<>"",O5<>"",O5>0,O5<999),(E5-O5)/O5,"") | Q5: =IF(AND(E5<>"",O5<>"",O5<999),MAX(0,E5-O5)*0,"Vincular vol.") -> Vincular vol.
A6: 3 | I6: =IF(COUNTA(F6:H6)>0,AVERAGE(F6:H6),"") | K6: =IF(J6<>"",J6*1.15,"") | M6: =IF(AND(L6<>""),"Calcular manual","") | O6: =IF(COUNTA(I6,K6,N6)>0,MIN(IF(I6<>"",I6,999),IF(K6<>"",K6,999),IF(N6<>"",N6,999)),"") -> 999 | P6: =IF(AND(E6<>"",O6<>"",O6>0,O6<999),(E6-O6)/O6,"") | Q6: =IF(AND(E6<>"",O6<>"",O6<999),MAX(0,E6-O6)*0,"Vincular vol.") -> Vincular vol.
A7: 4 | I7: =IF(COUNTA(F7:H7)>0,AVERAGE(F7:H7),"") | K7: =IF(J7<>"",J7*1.15,"") | M7: =IF(AND(L7<>""),"Calcular manual","") | O7: =IF(COUNTA(I7,K7,N7)>0,MIN(IF(I7<>"",I7,999),IF(K7<>"",K7,999),IF(N7<>"",N7,999)),"") -> 999 | P7: =IF(AND(E7<>"",O7<>"",O7>0,O7<999),(E7-O7)/O7,"") | Q7: =IF(AND(E7<>"",O7<>"",O7<999),MAX(0,E7-O7)*0,"Vincular vol.") -> Vincular vol.
A8: 5 | I8: =IF(COUNTA(F8:H8)>0,AVERAGE(F8:H8),"") | K8: =IF(J8<>"",J8*1.15,"") | M8: =IF(AND(L8<>""),"Calcular manual","") | O8: =IF(COUNTA(I8,K8,N8)>0,MIN(IF(I8<>"",I8,999),IF(K8<>"",K8,999),IF(N8<>"",N8,999)),"") -> 999 | P8: =IF(AND(E8<>"",O8<>"",O8>0,O8<999),(E8-O8)/O8,"") | Q8: =IF(AND(E8<>"",O8<>"",O8<999),MAX(0,E8-O8)*0,"Vincular vol.") -> Vincular vol.
A9: 6 | I9: =IF(COUNTA(F9:H9)>0,AVERAGE(F9:H9),"") | K9: =IF(J9<>"",J9*1.15,"") | M9: =IF(AND(L9<>""),"Calcular manual","") | O9: =IF(COUNTA(I9,K9,N9)>0,MIN(IF(I9<>"",I9,999),IF(K9<>"",K9,999),IF(N9<>"",N9,999)),"") -> 999 | P9: =IF(AND(E9<>"",O9<>"",O9>0,O9<999),(E9-O9)/O9,"") | Q9: =IF(AND(E9<>"",O9<>"",O9<999),MAX(0,E9-O9)*0,"Vincular vol.") -> Vincular vol.
A10: 7 | I10: =IF(COUNTA(F10:H10)>0,AVERAGE(F10:H10),"") | K10: =IF(J10<>"",J10*1.15,"") | M10: =IF(AND(L10<>""),"Calcular manual","") | O10: =IF(COUNTA(I10,K10,N10)>0,MIN(IF(I10<>"",I10,999),IF(K10<>"",K10,999),IF(N10<>"",N10,999)),"") -> 999 | P10: =IF(AND(E10<>"",O10<>"",O10>0,O10<999),(E10-O10)/O10,"") | Q10: =IF(AND(E10<>"",O10<>"",O10<999),MAX(0,E10-O10)*0,"Vincular vol.") -> Vincular vol.
A11: 8 | I11: =IF(COUNTA(F11:H11)>0,AVERAGE(F11:H11),"") | K11: =IF(J11<>"",J11*1.15,"") | M11: =IF(AND(L11<>""),"Calcular manual","") | O11: =IF(COUNTA(I11,K11,N11)>0,MIN(IF(I11<>"",I11,999),IF(K11<>"",K11,999),IF(N11<>"",N11,999)),"") -> 999 | P11: =IF(AND(E11<>"",O11<>"",O11>0,O11<999),(E11-O11)/O11,"") | Q11: =IF(AND(E11<>"",O11<>"",O11<999),MAX(0,E11-O11)*0,"Vincular vol.") -> Vincular vol.
A12: 9 | I12: =IF(COUNTA(F12:H12)>0,AVERAGE(F12:H12),"") | K12: =IF(J12<>"",J12*1.15,"") | M12: =IF(AND(L12<>""),"Calcular manual","") | O12: =IF(COUNTA(I12,K12,N12)>0,MIN(IF(I12<>"",I12,999),IF(K12<>"",K12,999),IF(N12<>"",N12,999)),"") -> 999 | P12: =IF(AND(E12<>"",O12<>"",O12>0,O12<999),(E12-O12)/O12,"") | Q12: =IF(AND(E12<>"",O12<>"",O12<999),MAX(0,E12-O12)*0,"Vincular vol.") -> Vincular vol.
A13: 10 | I13: =IF(COUNTA(F13:H13)>0,AVERAGE(F13:H13),"") | K13: =IF(J13<>"",J13*1.15,"") | M13: =IF(AND(L13<>""),"Calcular manual","") | O13: =IF(COUNTA(I13,K13,N13)>0,MIN(IF(I13<>"",I13,999),IF(K13<>"",K13,999),IF(N13<>"",N13,999)),"") -> 999 | P13: =IF(AND(E13<>"",O13<>"",O13>0,O13<999),(E13-O13)/O13,"") | Q13: =IF(AND(E13<>"",O13<>"",O13<999),MAX(0,E13-O13)*0,"Vincular vol.") -> Vincular vol.
A14: 11 | I14: =IF(COUNTA(F14:H14)>0,AVERAGE(F14:H14),"") | K14: =IF(J14<>"",J14*1.15,"") | M14: =IF(AND(L14<>""),"Calcular manual","") | O14: =IF(COUNTA(I14,K14,N14)>0,MIN(IF(I14<>"",I14,999),IF(K14<>"",K14,999),IF(N14<>"",N14,999)),"") -> 999 | P14: =IF(AND(E14<>"",O14<>"",O14>0,O14<999),(E14-O14)/O14,"") | Q14: =IF(AND(E14<>"",O14<>"",O14<999),MAX(0,E14-O14)*0,"Vincular vol.") -> Vincular vol.
A15: 12 | I15: =IF(COUNTA(F15:H15)>0,AVERAGE(F15:H15),"") | K15: =IF(J15<>"",J15*1.15,"") | M15: =IF(AND(L15<>""),"Calcular manual","") | O15: =IF(COUNTA(I15,K15,N15)>0,MIN(IF(I15<>"",I15,999),IF(K15<>"",K15,999),IF(N15<>"",N15,999)),"") -> 999 | P15: =IF(AND(E15<>"",O15<>"",O15>0,O15<999),(E15-O15)/O15,"") | Q15: =IF(AND(E15<>"",O15<>"",O15<999),MAX(0,E15-O15)*0,"Vincular vol.") -> Vincular vol.
... A33: 30 | I33: =IF(COUNTA(F33:H33)>0,AVERAGE(F33:H33),"") | K33: =IF(J33<>"",J33*1.15,"") | M33: =IF(AND(L33<>""),"Calcular manual","") | O33: =IF(COUNTA(I33,K33,N33)>0,MIN(IF(I33<>"",I33,999),IF(K33<>"",K33,999),IF(N33<>"",N33,999)),"") -> 999 | P33: =IF(AND(E33<>"",O33<>"",O33>0,O33<999),(E33-O33)/O33,"") | Q33: =IF(AND(E33<>"",O33<>"",O33<999),MAX(0,E33-O33)*0,"Vincular vol.") -> Vincular vol.
A35: PROTOCOLO (Cap.7.4): 1) Clasificar Pareto → 2) Commodities: DataComex TARIC → 3) Solicitar 3 cotiz. DAP → 4) Verificar prima ICIS → 5) Especialidades: cotizaciones fabricantes → 6) Tabla gap = potencial.
A36: CÓDIGOS TARIC: NaOH líquida=2815.12 | NaOH sólida=2815.11 | HCl=2806.10 | Hipocloritos=2828.90 | Tensoactivos=3402 | Preparaciones químicas=3824.90 | Floculantes=3906.90

Sheet Histórico Precios
A1: HISTÓRICO DE PRECIOS — 24 MESES
A2: Introducir precios de facturas reales. Usar €/kg de materia activa normalizado.
A3: Producto | B3: Proveedor | C3: Ene-24 | D3: Feb-24 | E3: Mar-24 | F3: Abr-24 | G3: May-24 | H3: Jun-24 | I3: Jul-24 | J3: Ago-24 | K3: Sep-24 | L3: Oct-24 | M3: Nov-24 | N3: Dic-24 | O3: Ene-25 | P3: Feb-25 | Q3: Mar-25 | R3: Abr-25 | S3: May-25 | T3: Jun-25 | U3: Jul-25 | V3: Ago-25 | W3: Sep-25 | X3: Oct-25 | Y3: Nov-25 | Z3: Dic-25 | AA3: Media Pond. 12m (Baseline) | AB3: Var. 24m (%)
AA4: =IF(COUNTA(O4:Z4)>0,AVERAGE(O4:Z4),"") | AB4: =IF(AND(C4<>"",Z4<>""),(Z4-C4)/C4,"")
AA5: =IF(COUNTA(O5:Z5)>0,AVERAGE(O5:Z5),"") | AB5: =IF(AND(C5<>"",Z5<>""),(Z5-C5)/C5,"")
AA6: =IF(COUNTA(O6:Z6)>0,AVERAGE(O6:Z6),"") | AB6: =IF(AND(C6<>"",Z6<>""),(Z6-C6)/C6,"")
AA7: =IF(COUNTA(O7:Z7)>0,AVERAGE(O7:Z7),"") | AB7: =IF(AND(C7<>"",Z7<>""),(Z7-C7)/C7,"")
AA8: =IF(COUNTA(O8:Z8)>0,AVERAGE(O8:Z8),"") | AB8: =IF(AND(C8<>"",Z8<>""),(Z8-C8)/C8,"")
AA9: =IF(COUNTA(O9:Z9)>0,AVERAGE(O9:Z9),"") | AB9: =IF(AND(C9<>"",Z9<>""),(Z9-C9)/C9,"")
AA10: =IF(COUNTA(O10:Z10)>0,AVERAGE(O10:Z10),"") | AB10: =IF(AND(C10<>"",Z10<>""),(Z10-C10)/C10,"")
AA11: =IF(COUNTA(O11:Z11)>0,AVERAGE(O11:Z11),"") | AB11: =IF(AND(C11<>"",Z11<>""),(Z11-C11)/C11,"")
AA12: =IF(COUNTA(O12:Z12)>0,AVERAGE(O12:Z12),"") | AB12: =IF(AND(C12<>"",Z12<>""),(Z12-C12)/C12,"")
AA13: =IF(COUNTA(O13:Z13)>0,AVERAGE(O13:Z13),"") | AB13: =IF(AND(C13<>"",Z13<>""),(Z13-C13)/C13,"")
AA14: =IF(COUNTA(O14:Z14)>0,AVERAGE(O14:Z14),"") | AB14: =IF(AND(C14<>"",Z14<>""),(Z14-C14)/C14,"")
AA15: =IF(COUNTA(O15:Z15)>0,AVERAGE(O15:Z15),"") | AB15: =IF(AND(C15<>"",Z15<>""),(Z15-C15)/C15,"")
... AA33: =IF(COUNTA(O33:Z33)>0,AVERAGE(O33:Z33),"") | AB33: =IF(AND(C33<>"",Z33<>""),(Z33-C33)/C33,"")

Sheet Visita Planta
A1: CHECKLIST DE VISITA A PLANTA
A2: Sección 1.4 del Manual — Completar el mismo día de la visita
A3: Cliente:
A4: Planta/Centro:
A5: Fecha visita:
A6: Acompañante(s):
A7: Consultor:
A9: Punto de inspección | B9: Estado (✓/✗/N/A) | C9: Observaciones / Detalle | D9: Foto (Sí/No) | E9: Oportunidad detectada | F9: Impacto estimado (€/año)
A10: ZONA DE RECEPCIÓN Y DESCARGA
A11: ¿Cómo llegan los productos? (cisterna/IBC/bidón)
A12: ¿Hay zona cubierta y rampa de descarga?
A13: ¿Báscula en recepción para verificar pesos?
A14: Frecuencia de entregas (diaria/semanal/mensual)
A15: ¿Llegan varios proveedores para mismo producto?
A16: ALMACÉN DE QUÍMICOS
A17: ¿Bidones/IBCs a medio usar?
A18: ¿Productos caducados o etiqueta deteriorada?
A19: ¿Duplicidades (2+ productos para misma función)?
A20: Marcas premium donde podría usar genérico
A21: Formato envase inadecuado (bidón cuando debería ser granel)
... A52: RESUMEN DE OPORTUNIDADES DETECTADAS
A53: Oportunidad | B53: Tipo (precio/formato/proceso/logística) | C53: Producto(s) afectado(s) | D53: Ahorro estimado (€/año) | E53: Dificultad (Baja/Media/Alta) | F53: Prioridad (1-5)

Sheet Proveedores
A1: REGISTRO DE PROVEEDORES
A2: Datos de contacto y clasificación
A3: Nº | B3: Proveedor | C3: Tipo (Fabricante/Distribuidor) | D3: Productos Suministrados | E3: Contacto Comercial | F3: Email | G3: Teléfono | H3: Web | I3: Cobertura Geográfica | J3: Valoración Servicio (1-5) | K3: ¿Alternativa viable? | L3: Observaciones
A4: 1
A5: 2
A6: 3
A7: 4
A8: 5
A9: 6
A10: 7
A11: 8
A12: 9
A13: 10
A14: 11
A15: 12
... A28: 25
A30: REFERENCIA: Distribuidores principales España (Cap.7.1A del Manual). Pre-completar con datos de contacto al inicio del proyecto.
B31: Brenntag España | C31: Distribuidor nacional | H31: brenntag.com/es-es
B32: Univar Solutions | C32: Distribuidor internacional | H32: univarsolutions.com/es
B33: Quimidroga | C33: Distribuidor nacional | H33: quimidroga.com
B34: Barcelonesa de Drogas | C34: Distribuidor nacional | H34: barcelonesa.com
B35: Acideka | C35: Distribuidor nacional | H35: acideka.com
